Workbook

Sheet Данные
A1: Отбор | B1: Квартал | C1: Дата | D1: 1 квартал | E1: 2 квартал | F1: 3 квартал | G1: 4 квартал | H1: 1-4 квартал минимум | I1: 1-4 квартал максимум | J1: best-effort
A2: 7500000 | B2: 1 квартал | C2: 44927 | D2: =$L$8 -> 10400000 | H2: =IF((H3-$L$8)>0,(H3-$L$8),0) -> 2400000 | I2: =D2 -> 10400000 | J2: =$L$8+$L$9 -> 20000000 | K2: Год контракт | L2: 2900000000
A3: =A2+7500000 -> 15000000 | C3: 44928 | D3: =IF(($L$8+D2)<($L$2-$L$4),$L$8+D2,$L$2-$L$7) -> 20800000 | H3: =IF((H4-$L$8)>0,(H4-$L$8),0) -> 12800000 | I3: =D3 -> 20800000 | J3: =IF(($L$8+$L$9+J2)<($L$2-$L$7),$L$8+$L$9+J2,$L$2-$L$7) -> 40000000 | K3: Год минимум | L3: 2320000000
A4: =A3+7500000 -> 22500000 | C4: 44929 | D4: =IF(($L$8+D3)<($L$2-$L$4),$L$8+D3,$L$2-$L$7) -> 31200000 | H4: =IF((H5-$L$8)>0,(H5-$L$8),0) -> 23200000 | I4: =D4 -> 31200000 | J4: =IF(($L$8+$L$9+J3)<($L$2-$L$7),$L$8+$L$9+J3,$L$2-$L$7) -> 60000000 | K4: 1 квартал минимум | L4: 928000000
A5: =A4+7500000 -> 30000000 | C5: 44930 | D5: =IF(($L$8+D4)<($L$2-$L$4),$L$8+D4,$L$2-$L$7) -> 41600000 | H5: =IF((H6-$L$8)>0,(H6-$L$8),0) -> 33600000 | I5: =D5 -> 41600000 | J5: =IF(($L$8+$L$9+J4)<($L$2-$L$7),$L$8+$L$9+J4,$L$2-$L$7) -> 80000000 | K5: 2 квартал максимум | L5: 493000000
A6: =A5+7500000 -> 37500000 | C6: 44931 | D6: =IF(($L$8+D5)<($L$2-$L$4),$L$8+D5,$L$2-$L$7) -> 52000000 | H6: =IF((H7-$L$8)>0,(H7-$L$8),0) -> 44000000 | I6: =D6 -> 52000000 | J6: =IF(($L$8+$L$9+J5)<($L$2-$L$7),$L$8+$L$9+J5,$L$2-$L$7) -> 100000000 | K6: 3 квартал максимум | L6: 493000000
A7: =A6+7500000 -> 45000000 | C7: 44932 | D7: =IF(($L$8+D6)<($L$2-$L$4),$L$8+D6,$L$2-$L$7) -> 62400000 | H7: =IF((H8-$L$8)>0,(H8-$L$8),0) -> 54400000 | I7: =D7 -> 62400000 | J7: =IF(($L$8+$L$9+J6)<($L$2-$L$7),$L$8+$L$9+J6,$L$2-$L$7) -> 120000000 | K7: 4 квартал минимум | L7: 928000000
A8: =A7+7500000 -> 52500000 | C8: 44933 | D8: =IF(($L$8+D7)<($L$2-$L$4),$L$8+D7,$L$2-$L$7) -> 72800000 | H8: =IF((H9-$L$8)>0,(H9-$L$8),0) -> 64800000 | I8: =D8 -> 72800000 | J8: =IF(($L$8+$L$9+J7)<($L$2-$L$7),$L$8+$L$9+J7,$L$2-$L$7) -> 140000000 | K8: Сутки контракт | L8: 10400000
A9: =A8+7500000 -> 60000000 | C9: 44934 | D9: =IF(($L$8+D8)<($L$2-$L$4),$L$8+D8,$L$2-$L$7) -> 83200000 | H9: =IF((H10-$L$8)>0,(H10-$L$8),0) -> 75200000 | I9: =D9 -> 83200000 | J9: =IF(($L$8+$L$9+J8)<($L$2-$L$7),$L$8+$L$9+J8,$L$2-$L$7) -> 160000000 | K9: best-effort | L9: 9600000
A10: =A9+7500000 -> 67500000 | C10: 44935 | D10: =IF(($L$8+D9)<($L$2-$L$4),$L$8+D9,$L$2-$L$7) -> 93600000 | H10: =IF((H11-$L$8)>0,(H11-$L$8),0) -> 85600000 | I10: =D10 -> 93600000 | J10: =IF(($L$8+$L$9+J9)<($L$2-$L$7),$L$8+$L$9+J9,$L$2-$L$7) -> 180000000
A11: =A10+7500000 -> 75000000 | C11: 44936 | D11: =IF(($L$8+D10)<($L$2-$L$4),$L$8+D10,$L$2-$L$7) -> 104000000 | H11: =IF((H12-$L$8)>0,(H12-$L$8),0) -> 96000000 | I11: =D11 -> 104000000 | J11: =IF(($L$8+$L$9+J10)<($L$2-$L$7),$L$8+$L$9+J10,$L$2-$L$7) -> 200000000
A12: =A11+7500000 -> 82500000 | C12: 44937 | D12: =IF(($L$8+D11)<($L$2-$L$4),$L$8+D11,$L$2-$L$7) -> 114400000 | H12: =IF((H13-$L$8)>0,(H13-$L$8),0) -> 106400000 | I12: =D12 -> 114400000 | J12: =IF(($L$8+$L$9+J11)<($L$2-$L$7),$L$8+$L$9+J11,$L$2-$L$7) -> 220000000
A13: =A12+7500000 -> 90000000 | C13: 44938 | D13: =IF(($L$8+D12)<($L$2-$L$4),$L$8+D12,$L$2-$L$7) -> 124800000 | H13: =IF((H14-$L$8)>0,(H14-$L$8),0) -> 116800000 | I13: =D13 -> 124800000 | J13: =IF(($L$8+$L$9+J12)<($L$2-$L$7),$L$8+$L$9+J12,$L$2-$L$7) -> 240000000
A14: =A13+7500000 -> 97500000 | C14: 44939 | D14: =IF(($L$8+D13)<($L$2-$L$4),$L$8+D13,$L$2-$L$7) -> 135200000 | H14: =IF((H15-$L$8)>0,(H15-$L$8),0) -> 127200000 | I14: =D14 -> 135200000 | J14: =IF(($L$8+$L$9+J13)<($L$2-$L$7),$L$8+$L$9+J13,$L$2-$L$7) -> 260000000
A15: =A14+7500000 -> 105000000 | C15: 44940 | D15: =IF(($L$8+D14)<($L$2-$L$4),$L$8+D14,$L$2-$L$7) -> 145600000 | H15: =IF((H16-$L$8)>0,(H16-$L$8),0) -> 137600000 | I15: =D15 -> 145600000 | J15: =IF(($L$8+$L$9+J14)<($L$2-$L$7),$L$8+$L$9+J14,$L$2-$L$7) -> 280000000
A16: =A15+7500000 -> 112500000 | C16: 44941 | D16: =IF(($L$8+D15)<($L$2-$L$4),$L$8+D15,$L$2-$L$7) -> 156000000 | H16: =IF((H17-$L$8)>0,(H17-$L$8),0) -> 148000000 | I16: =D16 -> 156000000 | J16: =IF(($L$8+$L$9+J15)<($L$2-$L$7),$L$8+$L$9+J15,$L$2-$L$7) -> 300000000
A17: =A16+7500000 -> 120000000 | C17: 44942 | D17: =IF(($L$8+D16)<($L$2-$L$4),$L$8+D16,$L$2-$L$7) -> 166400000 | H17: =IF((H18-$L$8)>0,(H18-$L$8),0) -> 158400000 | I17: =D17 -> 166400000 | J17: =IF(($L$8+$L$9+J16)<($L$2-$L$7),$L$8+$L$9+J16,$L$2-$L$7) -> 320000000
A18: =A17+7500000 -> 127500000 | C18: 44943 | D18: =IF(($L$8+D17)<($L$2-$L$4),$L$8+D17,$L$2-$L$7) -> 176800000 | H18: =IF((H19-$L$8)>0,(H19-$L$8),0) -> 168800000 | I18: =D18 -> 176800000 | J18: =IF(($L$8+$L$9+J17)<($L$2-$L$7),$L$8+$L$9+J17,$L$2-$L$7) -> 340000000
A19: =A18+7500000 -> 135000000 | C19: 44944 | D19: =IF(($L$8+D18)<($L$2-$L$4),$L$8+D18,$L$2-$L$7) -> 187200000 | H19: =IF((H20-$L$8)>0,(H20-$L$8),0) -> 179200000 | I19: =D19 -> 187200000 | J19: =IF(($L$8+$L$9+J18)<($L$2-$L$7),$L$8+$L$9+J18,$L$2-$L$7) -> 360000000
A20: =A19+7500000 -> 142500000 | C20: 44945 | D20: =IF(($L$8+D19)<($L$2-$L$4),$L$8+D19,$L$2-$L$7) -> 197600000 | H20: =IF((H21-$L$8)>0,(H21-$L$8),0) -> 189600000 | I20: =D20 -> 197600000 | J20: =IF(($L$8+$L$9+J19)<($L$2-$L$7),$L$8+$L$9+J19,$L$2-$L$7) -> 380000000
A21: =A20+7500000 -> 150000000 | C21: 44946 | D21: =IF(($L$8+D20)<($L$2-$L$4),$L$8+D20,$L$2-$L$7) -> 208000000 | H21: =IF((H22-$L$8)>0,(H22-$L$8),0) -> 200000000 | I21: =D21 -> 208000000 | J21: =IF(($L$8+$L$9+J20)<($L$2-$L$7),$L$8+$L$9+J20,$L$2-$L$7) -> 400000000
... A90: =A89+7500000 -> 667500000 | C90: 45015 | D90: =IF(($L$8+D89)<($L$2-$L$4),$L$8+D89,$L$2-$L$7) -> 925600000 | H90: =IF((H91-$L$8)>0,(H91-$L$8),0) -> 917600000 | I90: =D90 -> 925600000 | J90: =IF(($L$8+$L$9+J89)<($L$2-$L$7),$L$8+$L$9+J89,$L$2-$L$7) -> 1780000000
A91: =A90+7500000 -> 675000000 | C91: 45016 | D91: =IF(($L$8+D90)<($L$2-$L$4),$L$8+D90,$L$2-$L$7) -> 936000000 | H91: =L7 -> 928000000 | I91: =D91 -> 936000000 | J91: =IF(($L$8+$L$9+J90)<($L$2-$L$7),$L$8+$L$9+J90,$L$2-$L$7) -> 1800000000
A92: =A91+7500000 -> 682500000 | B92: 2 квартал | C92: 45017 | E92: =D91+$L$8 -> 946400000 | H92: =$L$7 -> 928000000 | I92: =E92 -> 946400000 | J92: =J91+$L$8+$L$9 -> 1820000000
A93: =A92+7500000 -> 690000000 | C93: 45018 | E93: =MIN(IF((E92+$L$8)<($E$92+$L$5),E92+$L$8,$E$92+$L$5),$L$2-$L$4) -> 956800000 | H93: =$L$7 -> 928000000 | I93: =E93 -> 956800000 | J93: =MIN(IF((J92+$L$8+$L$9)<($J$92+$L$5),J92+$L$9+$L$8,$J$92+$L$5),$L$2-$L$4) -> 1840000000
A94: =A93+7500000 -> 697500000 | C94: 45019 | E94: =MIN(IF((E93+$L$8)<($E$92+$L$5),E93+$L$8,$E$92+$L$5),$L$2-$L$4) -> 967200000 | H94: =$L$7 -> 928000000 | I94: =E94 -> 967200000 | J94: =MIN(IF((J93+$L$8+$L$9)<($J$92+$L$5),J93+$L$9+$L$8,$J$92+$L$5),$L$2-$L$4) -> 1860000000
A95: =A94+7500000 -> 705000000 | C95: 45020 | E95: =MIN(IF((E94+$L$8)<($E$92+$L$5),E94+$L$8,$E$92+$L$5),$L$2-$L$4) -> 977600000 | H95: =$L$7 -> 928000000 | I95: =E95 -> 977600000 | J95: =MIN(IF((J94+$L$8+$L$9)<($J$92+$L$5),J94+$L$9+$L$8,$J$92+$L$5),$L$2-$L$4) -> 1880000000
A96: =A95+7500000 -> 712500000 | C96: 45021 | E96: =MIN(IF((E95+$L$8)<($E$92+$L$5),E95+$L$8,$E$92+$L$5),$L$2-$L$4) -> 988000000 | H96: =$L$7 -> 928000000 | I96: =E96 -> 988000000 | J96: =MIN(IF((J95+$L$8+$L$9)<($J$92+$L$5),J95+$L$9+$L$8,$J$92+$L$5),$L$2-$L$4) -> 1900000000
A97: =A96+7500000 -> 720000000 | C97: 45022 | E97: =MIN(IF((E96+$L$8)<($E$92+$L$5),E96+$L$8,$E$92+$L$5),$L$2-$L$4) -> 998400000 | H97: =$L$7 -> 928000000 | I97: =E97 -> 998400000 | J97: =MIN(IF((J96+$L$8+$L$9)<($J$92+$L$5),J96+$L$9+$L$8,$J$92+$L$5),$L$2-$L$4) -> 1920000000
A98: =A97+7500000 -> 727500000 | C98: 45023 | E98: =MIN(IF((E97+$L$8)<($E$92+$L$5),E97+$L$8,$E$92+$L$5),$L$2-$L$4) -> 1008800000 | H98: =$L$7 -> 928000000 | I98: =E98 -> 1008800000 | J98: =MIN(IF((J97+$L$8+$L$9)<($J$92+$L$5),J97+$L$9+$L$8,$J$92+$L$5),$L$2-$L$4) -> 1940000000
A99: =A98+7500000 -> 735000000 | C99: 45024 | E99: =MIN(IF((E98+$L$8)<($E$92+$L$5),E98+$L$8,$E$92+$L$5),$L$2-$L$4) -> 1019200000 | H99: =$L$7 -> 928000000 | I99: =E99 -> 1019200000 | J99: =MIN(IF((J98+$L$8+$L$9)<($J$92+$L$5),J98+$L$9+$L$8,$J$92+$L$5),$L$2-$L$4) -> 1960000000
A100: =A99+7500000 -> 742500000 | C100: 45025 | E100: =MIN(IF((E99+$L$8)<($E$92+$L$5),E99+$L$8,$E$92+$L$5),$L$2-$L$4) -> 1029600000 | H100: =$L$7 -> 928000000 | I100: =E100 -> 1029600000 | J100: =MIN(IF((J99+$L$8+$L$9)<($J$92+$L$5),J99+$L$9+$L$8,$J$92+$L$5),$L$2-$L$4) -> 1972000000
A101: =A100+7500000 -> 750000000 | C101: 45026 | E101: =MIN(IF((E100+$L$8)<($E$92+$L$5),E100+$L$8,$E$92+$L$5),$L$2-$L$4) -> 1040000000 | H101: =$L$7 -> 928000000 | I101: =E101 -> 1040000000 | J101: =MIN(IF((J100+$L$8+$L$9)<($J$92+$L$5),J100+$L$9+$L$8,$J$92+$L$5),$L$2-$L$4) -> 1972000000
A102: =A101+7500000 -> 757500000 | C102: 45027 | E102: =MIN(IF((E101+$L$8)<($E$92+$L$5),E101+$L$8,$E$92+$L$5),$L$2-$L$4) -> 1050400000 | H102: =$L$7 -> 928000000 | I102: =E102 -> 1050400000 | J102: =MIN(IF((J101+$L$8+$L$9)<($J$92+$L$5),J101+$L$9+$L$8,$J$92+$L$5),$L$2-$L$4) -> 1972000000
A103: =A102+7500000 -> 765000000 | C103: 45028 | E103: =MIN(IF((E102+$L$8)<($E$92+$L$5),E102+$L$8,$E$92+$L$5),$L$2-$L$4) -> 1060800000 | H103: =$L$7 -> 928000000 | I103: =E103 -> 1060800000 | J103: =MIN(IF((J102+$L$8+$L$9)<($J$92+$L$5),J102+$L$9+$L$8,$J$92+$L$5),$L$2-$L$4) -> 1972000000
A104: =A103+7500000 -> 772500000 | C104: 45029 | E104: =MIN(IF((E103+$L$8)<($E$92+$L$5),E103+$L$8,$E$92+$L$5),$L$2-$L$4) -> 1071200000 | H104: =$L$7 -> 928000000 | I104: =E104 -> 1071200000 | J104: =MIN(IF((J103+$L$8+$L$9)<($J$92+$L$5),J103+$L$9+$L$8,$J$92+$L$5),$L$2-$L$4) -> 1972000000
... A177: =A176+7500000 -> 1320000000 | C177: 45102 | E177: =MIN(IF((E176+$L$8)<($E$92+$L$5),E176+$L$8,$E$92+$L$5),$L$2-$L$4) -> 1439400000 | H177: =$L$7 -> 928000000 | I177: =E177 -> 1439400000 | J177: =MIN(IF((J176+$L$8+$L$9)<($J$92+$L$5),J176+$L$9+$L$8,$J$92+$L$5),$L$2-$L$4) -> 1972000000
C178: 45103 | E178: =MIN(IF((E177+$L$8)<($E$92+$L$5),E177+$L$8,$E$92+$L$5),$L$2-$L$4) -> 1439400000 | H178: =$L$7 -> 928000000 | I178: =E178 -> 1439400000 | J178: =MIN(IF((J177+$L$8+$L$9)<($J$92+$L$5),J177+$L$9+$L$8,$J$92+$L$5),$L$2-$L$4) -> 1972000000
C179: 45104 | E179: =MIN(IF((E178+$L$8)<($E$92+$L$5),E178+$L$8,$E$92+$L$5),$L$2-$L$4) -> 1439400000 | H179: =$L$7 -> 928000000 | I179: =E179 -> 1439400000 | J179: =MIN(IF((J178+$L$8+$L$9)<($J$92+$L$5),J178+$L$9+$L$8,$J$92+$L$5),$L$2-$L$4) -> 1972000000
C180: 45105 | E180: =MIN(IF((E179+$L$8)<($E$92+$L$5),E179+$L$8,$E$92+$L$5),$L$2-$L$4) -> 1439400000 | H180: =$L$7 -> 928000000 | I180: =E180 -> 1439400000 | J180: =MIN(IF((J179+$L$8+$L$9)<($J$92+$L$5),J179+$L$9+$L$8,$J$92+$L$5),$L$2-$L$4) -> 1972000000
...

Sheet График
A1: Минимум | B1: Максимум | C1: best-effort | D1: Дата | E1: Отбор | F1: ГКК | G1: МГК
A2: {=Данные!H2:H366} -> 2400000 | B2: =Данные!I2-Данные!H2 -> 8000000 | C2: =Данные!J2-Данные!I2 -> 9600000 | D2: =Данные!C2 -> 44927 | E2: {=Данные!A2:A177} -> 7500000 | F2: 2900000000 | G2: 2320000000 | H2: 45016 | I2: 0
A3: 12800000 | B3: =Данные!I3-Данные!H3 -> 8000000 | C3: =Данные!J3-Данные!I3 -> 19200000 | D3: =Данные!C3 -> 44928 | E3: 15000000 | F3: 2900000000 | G3: 2320000000 | H3: 45016 | I3: 3000000000
A4: 23200000 | B4: =Данные!I4-Данные!H4 -> 8000000 | C4: =Данные!J4-Данные!I4 -> 28800000 | D4: =Данные!C4 -> 44929 | E4: 22500000 | F4: 2900000000 | G4: 2320000000 | H4: 45107 | I4: 0
A5: 33600000 | B5: =Данные!I5-Данные!H5 -> 8000000 | C5: =Данные!J5-Данные!I5 -> 38400000 | D5: =Данные!C5 -> 44930 | E5: 30000000 | F5: 2900000000 | G5: 2320000000 | H5: 45107 | I5: 3000000000
A6: 44000000 | B6: =Данные!I6-Данные!H6 -> 8000000 | C6: =Данные!J6-Данные!I6 -> 48000000 | D6: =Данные!C6 -> 44931 | E6: 37500000 | F6: 2900000000 | G6: 2320000000 | H6: 45199 | I6: 0
A7: 54400000 | B7: =Данные!I7-Данные!H7 -> 8000000 | C7: =Данные!J7-Данные!I7 -> 57600000 | D7: =Данные!C7 -> 44932 | E7: 45000000 | F7: 2900000000 | G7: 2320000000 | H7: 45199 | I7: 3000000000
A8: 64800000 | B8: =Данные!I8-Данные!H8 -> 8000000 | C8: =Данные!J8-Данные!I8 -> 67200000 | D8: =Данные!C8 -> 44933 | E8: 52500000 | F8: 2900000000 | G8: 2320000000 | H8: 45291 | I8: 0
A9: 75200000 | B9: =Данные!I9-Данные!H9 -> 8000000 | C9: =Данные!J9-Данные!I9 -> 76800000 | D9: =Данные!C9 -> 44934 | E9: 60000000 | F9: 2900000000 | G9: 2320000000 | H9: 45291 | I9: 3000000000
A10: 85600000 | B10: =Данные!I10-Данные!H10 -> 8000000 | C10: =Данные!J10-Данные!I10 -> 86400000 | D10: =Данные!C10 -> 44935 | E10: 67500000 | F10: 2900000000 | G10: 2320000000
A11: 96000000 | B11: =Данные!I11-Данные!H11 -> 8000000 | C11: =Данные!J11-Данные!I11 -> 96000000 | D11: =Данные!C11 -> 44936 | E11: 75000000 | F11: 2900000000 | G11: 2320000000
A12: 106400000 | B12: =Данные!I12-Данные!H12 -> 8000000 | C12: =Данные!J12-Данные!I12 -> 105600000 | D12: =Данные!C12 -> 44937 | E12: 82500000 | F12: 2900000000 | G12: 2320000000
A13: 116800000 | B13: =Данные!I13-Данные!H13 -> 8000000 | C13: =Данные!J13-Данные!I13 -> 115200000 | D13: =Данные!C13 -> 44938 | E13: 90000000 | F13: 2900000000 | G13: 2320000000
A14: 127200000 | B14: =Данные!I14-Данные!H14 -> 8000000 | C14: =Данные!J14-Данные!I14 -> 124800000 | D14: =Данные!C14 -> 44939 | E14: 97500000 | F14: 2900000000 | G14: 2320000000
A15: 137600000 | B15: =Данные!I15-Данные!H15 -> 8000000 | C15: =Данные!J15-Данные!I15 -> 134400000 | D15: =Данные!C15 -> 44940 | E15: 105000000 | F15: 2900000000 | G15: 2320000000
A16: 148000000 | B16: =Данные!I16-Данные!H16 -> 8000000 | C16: =Данные!J16-Данные!I16 -> 144000000 | D16: =Данные!C16 -> 44941 | E16: 112500000 | F16: 2900000000 | G16: 2320000000
A17: 158400000 | B17: =Данные!I17-Данные!H17 -> 8000000 | C17: =Данные!J17-Данные!I17 -> 153600000 | D17: =Данные!C17 -> 44942 | E17: 120000000 | F17: 2900000000 | G17: 2320000000
A18: 168800000 | B18: =Данные!I18-Данные!H18 -> 8000000 | C18: =Данные!J18-Данные!I18 -> 163200000 | D18: =Данные!C18 -> 44943 | E18: 127500000 | F18: 2900000000 | G18: 2320000000
A19: 179200000 | B19: =Данные!I19-Данные!H19 -> 8000000 | C19: =Данные!J19-Данные!I19 -> 172800000 | D19: =Данные!C19 -> 44944 | E19: 135000000 | F19: 2900000000 | G19: 2320000000
A20: 189600000 | B20: =Данные!I20-Данные!H20 -> 8000000 | C20: =Данные!J20-Данные!I20 -> 182400000 | D20: =Данные!C20 -> 44945 | E20: 142500000 | F20: 2900000000 | G20: 2320000000
A21: 200000000 | B21: =Данные!I21-Данные!H21 -> 8000000 | C21: =Данные!J21-Данные!I21 -> 192000000 | D21: =Данные!C21 -> 44946 | E21: 150000000 | F21: 2900000000 | G21: 2320000000
... A91: 928000000 | B91: =Данные!I91-Данные!H91 -> 8000000 | C91: =Данные!J91-Данные!I91 -> 864000000 | D91: =Данные!C91 -> 45016 | E91: 675000000 | F91: 2900000000 | G91: 2320000000
A92: 928000000 | B92: =Данные!I92-Данные!H92 -> 18400000 | C92: =Данные!J92-Данные!I92 -> 873600000 | D92: =Данные!C92 -> 45017 | E92: 682500000 | F92: 2900000000 | G92: 2320000000 | I92: 493000000
A93: 928000000 | B93: =Данные!I93-Данные!H93 -> 28800000 | C93: =Данные!J93-Данные!I93 -> 883200000 | D93: =Данные!C93 -> 45018 | E93: 690000000 | F93: 2900000000 | G93: 2320000000 | I93: 493000000
A94: 928000000 | B94: =Данные!I94-Данные!H94 -> 39200000 | C94: =Данные!J94-Данные!I94 -> 892800000 | D94: =Данные!C94 -> 45019 | E94: 697500000 | F94: 2900000000 | G94: 2320000000 | I94: 493000000
A95: 928000000 | B95: =Данные!I95-Данные!H95 -> 49600000 | C95: =Данные!J95-Данные!I95 -> 902400000 | D95: =Данные!C95 -> 45020 | E95: 705000000 | F95: 2900000000 | G95: 2320000000 | I95: 493000000
A96: 928000000 | B96: =Данные!I96-Данные!H96 -> 60000000 | C96: =Данные!J96-Данные!I96 -> 912000000 | D96: =Данные!C96 -> 45021 | E96: 712500000 | F96: 2900000000 | G96: 2320000000 | I96: 493000000
A97: 928000000 | B97: =Данные!I97-Данные!H97 -> 70400000 | C97: =Данные!J97-Данные!I97 -> 921600000 | D97: =Данные!C97 -> 45022 | E97: 720000000 | F97: 2900000000 | G97: 2320000000 | I97: 493000000
A98: 928000000 | B98: =Данные!I98-Данные!H98 -> 80800000 | C98: =Данные!J98-Данные!I98 -> 931200000 | D98: =Данные!C98 -> 45023 | E98: 727500000 | F98: 2900000000 | G98: 2320000000 | I98: 493000000
A99: 928000000 | B99: =Данные!I99-Данные!H99 -> 91200000 | C99: =Данные!J99-Данные!I99 -> 940800000 | D99: =Данные!C99 -> 45024 | E99: 735000000 | F99: 2900000000 | G99: 2320000000 | I99: 493000000
A100: 928000000 | B100: =Данные!I100-Данные!H100 -> 101600000 | C100: =Данные!J100-Данные!I100 -> 942400000 | D100: =Данные!C100 -> 45025 | E100: 742500000 | F100: 2900000000 | G100: 2320000000 | I100: 493000000
A101: 928000000 | B101: =Данные!I101-Данные!H101 -> 112000000 | C101: =Данные!J101-Данные!I101 -> 932000000 | D101: =Данные!C101 -> 45026 | E101: 750000000 | F101: 2900000000 | G101: 2320000000 | I101: 493000000
A102: 928000000 | B102: =Данные!I102-Данные!H102 -> 122400000 | C102: =Данные!J102-Данные!I102 -> 921600000 | D102: =Данные!C102 -> 45027 | E102: 757500000 | F102: 2900000000 | G102: 2320000000 | I102: 493000000
A103: 928000000 | B103: =Данные!I103-Данные!H103 -> 132800000 | C103: =Данные!J103-Данные!I103 -> 911200000 | D103: =Данные!C103 -> 45028 | E103: 765000000 | F103: 2900000000 | G103: 2320000000 | I103: 493000000
... A177: 928000000 | B177: =Данные!I177-Данные!H177 -> 511400000 | C177: =Данные!J177-Данные!I177 -> 532600000 | D177: =Данные!C177 -> 45102 | E177: 1320000000 | F177: 2900000000 | G177: 2320000000 | I177: 493000000
A178: 928000000 | B178: =Данные!I178-Данные!H178 -> 511400000 | C178: =Данные!J178-Данные!I178 -> 532600000 | D178: =Данные!C178 -> 45103 | F178: 2900000000 | G178: 2320000000 | I178: 493000000
A179: 928000000 | B179: =Данные!I179-Данные!H179 -> 511400000 | C179: =Данные!J179-Данные!I179 -> 532600000 | D179: =Данные!C179 -> 45104 | F179: 2900000000 | G179: 2320000000 | I179: 493000000
A180: 928000000 | B180: =Данные!I180-Данные!H180 -> 511400000 | C180: =Данные!J180-Данные!I180 -> 532600000 | D180: =Данные!C180 -> 45105 | F180: 2900000000 | G180: 2320000000 | I180: 493000000
A181: 928000000 | B181: =Данные!I181-Данные!H181 -> 511400000 | C181: =Данные!J181-Данные!I181 -> 532600000 | D181: =Данные!C181 -> 45106 | F181: 2900000000 | G181: 2320000000 | I181: 493000000
A182: 928000000 | B182: =Данные!I182-Данные!H182 -> 511400000 | C182: =Данные!J182-Данные!I182 -> 532600000 | D182: =Данные!C182 -> 45107 | F182: 2900000000 | G182: 2320000000 | I182: 493000000
...
