Workbook

Sheet Текущий контракт
A1: Дата | B1: Австрия | C1: Процесс | D1: Остаток тыс. куб. | E1: Выручка тыс. ЕВРО | F1: Венгрия | G1: Процесс | H1: Остаток тыс. куб. | I1: Выручка тыс. ЕВРО | J1: Сумма выручки
A2: 44013 | B2: 200000 | C2: Отбор | D2: =N2-N6 -> 44550 | E2: =$N$6*L13-N4 -> 30265 | H2: 5000 | I2: =(H2-H3)*$M$13 -> 0 | J2: =E2+I2 -> 30265 | K2: Остаток газа на ПХГ Австрия, тыс. куб. | N2: 45000
A3: 44014 | C3: Отбор | D3: =D2-$N$6 -> 44100 | E3: =(D2-D3)*$L$13 -> 30465 | H3: 5000 | I3: =(H3-H4)*$M$13 -> 0 | J3: =E3+I3 -> 30465 | K3: Остаток газа на ПХГ Венгрия, тыс. куб. | N3: 5000
A4: 44015 | C4: Отбор | D4: =D3-$N$6 -> 43650 | E4: =(D3-D4)*$L$13 -> 30465 | H4: 5000 | I4: =(H4-H5)*$M$13 -> 0 | J4: =E4+I4 -> 30465 | K4: Хранение в месяц, тыс ЕВРО | N4: 200
A5: 44016 | C5: Отбор | D5: =D4-$N$6 -> 43200 | E5: =(D4-D5)*$L$13 -> 30465 | H5: 5000 | I5: =(H5-H6)*$M$13 -> 0 | J5: =E5+I5 -> 30465 | K5: Цена продажи неотобранного газа ЕВРО/тыс. куб. | N5: =L15-3 -> 73.9
A6: 44017 | C6: Отбор | D6: =D5-$N$6 -> 42750 | E6: =(D5-D6)*$L$13 -> 30465 | H6: 5000 | I6: =(H6-H7)*$M$13 -> 0 | J6: =E6+I6 -> 30465 | K6: Суточный отбор Австрия, тыс.куб. | N6: 450
A7: 44018 | C7: Отбор | D7: =D6-$N$6 -> 42300 | E7: =(D6-D7)*$L$13 -> 30465 | H7: 5000 | I7: =(H7-H8)*$M$13 -> 0 | J7: =E7+I7 -> 30465 | K7: Суточный отбор Венгрия, тыс.куб. | N7: 120
A8: 44019 | C8: Отбор | D8: =D7-$N$6 -> 41850 | E8: =(D7-D8)*$L$13 -> 30465 | H8: 5000 | I8: =(H8-H9)*$M$13 -> 0 | J8: =E8+I8 -> 30465 | K8: Суточная закачка Австрия, тыс. куб | N8: 870
A9: 44020 | C9: Отбор | D9: =D8-$N$6 -> 41400 | E9: =(D8-D9)*$L$13 -> 30465 | H9: 5000 | I9: =(H9-H10)*$M$13 -> 0 | J9: =E9+I9 -> 30465 | K9: Вход в Венгрию из ПХГ тыс.куб. | N9: 3.08
A10: 44021 | C10: Отбор | D10: =D9-$N$6 -> 40950 | E10: =(D9-D10)*$L$13 -> 30465 | H10: 5000 | I10: =(H10-H11)*$M$13 -> 0 | J10: =E10+I10 -> 30465 | K10: Выход из Венгрии в ПХГ тыс.куб. | N10: 3.29
A11: 44022 | C11: Отбор | D11: =D10-$N$6 -> 40500 | E11: =(D10-D11)*$L$13 -> 30465 | H11: 5000 | I11: =(H11-H12)*$M$13 -> 0 | J11: =E11+I11 -> 30465
A12: 44023 | C12: Отбор | D12: =D11-$N$6 -> 40050 | E12: =(D11-D12)*$L$13 -> 30465 | H12: 5000 | I12: =(H12-H13)*$M$13 -> 0 | J12: =E12+I12 -> 30465 | L12: VTPA (Австрия) | M12: VTPH (Венгрия)
A13: 44024 | C13: Отбор | D13: =D12-$N$6 -> 39600 | E13: =(D12-D13)*$L$13 -> 30465 | H13: 5000 | I13: =(H13-H14)*$M$13 -> 0 | J13: =E13+I13 -> 30465 | K13: июль 2020 | L13: 67.7 | M13: 88.3
A14: 44025 | C14: Отбор | D14: =D13-$N$6 -> 39150 | E14: =(D13-D14)*$L$13 -> 30465 | H14: 5000 | I14: =(H14-H15)*$M$13 -> 0 | J14: =E14+I14 -> 30465 | K14: август 2020 | L14: 69.6 | M14: 93.8
A15: 44026 | C15: Отбор | D15: =D14-$N$6 -> 38700 | E15: =(D14-D15)*$L$13 -> 30465 | H15: 5000 | I15: =(H15-H16)*$M$13 -> 0 | J15: =E15+I15 -> 30465 | K15: сентябрь 2020 | L15: 76.9 | M15: 103
A16: 44027 | C16: Отбор | D16: =D15-$N$6 -> 38250 | E16: =(D15-D16)*$L$13 -> 30465 | H16: 5000 | I16: =(H16-H17)*$M$13 -> 0 | J16: =E16+I16 -> 30465 | K16: октябрь 2020 | L16: 93.2 | M16: 122.6
A17: 44028 | C17: Отбор | D17: =D16-$N$6 -> 37800 | E17: =(D16-D17)*$L$13 -> 30465 | H17: 5000 | I17: =(H17-H18)*$M$13 -> 0 | J17: =E17+I17 -> 30465 | K17: ноябрь 2020 | L17: 133.7 | M17: 157
A18: 44029 | C18: Отбор | D18: =D17-$N$6 -> 37350 | E18: =(D17-D18)*$L$13 -> 30465 | H18: 5000 | I18: =(H18-H19)*$M$13 -> 0 | J18: =E18+I18 -> 30465 | K18: декабрь 2020 | L18: 133.7 | M18: 168.8
A19: 44030 | C19: Отбор | D19: =D18-$N$6 -> 36900 | E19: =(D18-D19)*$L$13 -> 30465 | H19: 5000 | I19: =(H19-H20)*$M$13 -> 0 | J19: =E19+I19 -> 30465 | K19: январь 2021 | L19: 142 | M19: 172
A20: 44031 | C20: Отбор | D20: =D19-$N$6 -> 36450 | E20: =(D19-D20)*$L$13 -> 30465 | H20: 5000 | I20: =(H20-H21)*$M$13 -> 0 | J20: =E20+I20 -> 30465 | K20: 1 кв. 2021 | L20: 141.1 | M20: 171.2
A21: 44032 | C21: Отбор | D21: =D20-$N$6 -> 36000 | E21: =(D20-D21)*$L$13 -> 30465 | H21: 5000 | I21: =(H21-H22)*$M$13 -> 0 | J21: =E21+I21 -> 30465 | K21: 2 кв. 2021 | L21: 137 | M21: 162.3
A22: 44033 | C22: Отбор | D22: =D21-$N$6 -> 35550 | E22: =(D21-D22)*$L$13 -> 30465 | H22: 5000 | I22: =(H22-H23)*$M$13 -> 0 | J22: =E22+I22 -> 30465
A23: 44034 | C23: Отбор | D23: =D22-$N$6 -> 35100 | E23: =(D22-D23)*$L$13 -> 30465 | H23: 5000 | I23: =(H23-H24)*$M$13 -> 0 | J23: =E23+I23 -> 30465 | K23: Доля рынка,%
A24: 44035 | C24: Отбор | D24: =D23-$N$6 -> 34650 | E24: =(D23-D24)*$L$13 -> 30465 | H24: 5000 | I24: =(H24-H25)*$M$13 -> 0 | J24: =E24+I24 -> 30465 | L24: Австрия | M24: =NPV(0.1,E2:E367,A2:A367) -> 305023.43 | N24: =M24/(M24+M25)*100 -> 99.679678
A25: 44036 | C25: Отбор | D25: =D24-$N$6 -> 34200 | E25: =(D24-D25)*$L$13 -> 30465 | H25: 5000 | I25: =(H25-H26)*$M$13 -> 0 | J25: =E25+I25 -> 30465 | L25: Венгрия | M25: =NPV(0.1,I2:I367,A2:A367) -> 980.19744 | N25: =M25/(M24+M25)*100 -> 0.32032217
A26: 44037 | C26: Отбор | D26: =D25-$N$6 -> 33750 | E26: =(D25-D26)*$L$13 -> 30465 | H26: 5000 | I26: =(H26-H27)*$M$13 -> 0 | J26: =E26+I26 -> 30465 | K26: Денежные потоки контракт
A27: 44038 | C27: Отбор | D27: =D26-$N$6 -> 33300 | E27: =(D26-D27)*$L$13 -> 30465 | H27: 5000 | I27: =(H27-H28)*$M$13 -> 0 | J27: =E27+I27 -> 30465 | L27: 3 квартал 2020 | M27: =SUM(J2:J93) -> 3921865
A28: 44039 | C28: Отбор | D28: =D27-$N$6 -> 32850 | E28: =(D27-D28)*$L$13 -> 30465 | H28: 5000 | I28: =(H28-H29)*$M$13 -> 0 | J28: =E28+I28 -> 30465 | L28: 4 квартал 2020 | M28: =SUM(J94:J185) -> -600
A29: 44040 | C29: Отбор | D29: =D28-$N$6 -> 32400 | E29: =(D28-D29)*$L$13 -> 30465 | H29: 5000 | I29: =(H29-H30)*$M$13 -> 0 | J29: =E29+I29 -> 30465 | L29: 1 квартал 2021 | M29: =SUM(J186:J275) -> 5713950
A30: 44041 | C30: Отбор | D30: =D29-$N$6 -> 31950 | E30: =(D29-D30)*$L$13 -> 30465 | H30: 5000 | I30: =(H30-H31)*$M$13 -> 0 | J30: =E30+I30 -> 30465 | L30: 2 квартал 2021 | M30: =SUM(J276:J367) -> 5572850
A31: 44042 | C31: Отбор | D31: =D30-$N$6 -> 31500 | E31: =(D30-D31)*$L$13 -> 30465 | H31: 5000 | I31: =(H31-H32)*$M$13 -> 0 | J31: =E31+I31 -> 30465 | K31: Денежные потоки предложение
A32: 44043 | C32: Отбор | D32: =D31-$N$6 -> 31050 | E32: =(D31-D32)*$L$13 -> 30465 | H32: 5000 | I32: =(H32-H33)*$M$13 -> 0 | J32: =E32+I32 -> 30465 | L32: 3 квартал 2020 | M32: =SUM(Предложение!E2:E93) -> 2950000
A33: 44044 | B33: 200000 | C33: Отбор | D33: =D32-$N$6 -> 30600 | E33: =(D32-D33)*$L$14-N4 -> 31120 | H33: 5000 | I33: =(H33-H34)*$M$13 -> 0 | J33: =E33+I33 -> 31120 | L33: 4 квартал 2020 | M33: =SUM(Предложение!E94:E185) -> -496242.67
A34: 44045 | C34: Отбор | D34: =D33-$N$6 -> 30150 | E34: =(D33-D34)*$L$14 -> 31320 | H34: 5000 | I34: =(H34-H35)*$M$13 -> 0 | J34: =E34+I34 -> 31320 | L34: 1 квартал 2021 | M34: =SUM(Предложение!E186:E274) -> 11200561
A35: 44046 | C35: Отбор | D35: =D34-$N$6 -> 29700 | E35: =(D34-D35)*$L$14 -> 31320 | H35: 5000 | I35: =(H35-H36)*$M$13 -> 0 | J35: =E35+I35 -> 31320 | L35: 2 квартал 2021 | M35: =SUM(Предложение!E276:E367) -> 0
A36: 44047 | C36: Отбор | D36: =D35-$N$6 -> 29250 | E36: =(D35-D36)*$L$14 -> 31320 | H36: 5000 | I36: =(H36-H37)*$M$13 -> 0 | J36: =E36+I36 -> 31320 | K36: Хранение
A37: 44048 | C37: Отбор | D37: =D36-$N$6 -> 28800 | E37: =(D36-D37)*$L$14 -> 31320 | H37: 5000 | I37: =(H37-H38)*$M$13 -> 0 | J37: =E37+I37 -> 31320 | L37: Контракт | M37: =E373 -> 1501016.6
A38: 44049 | C38: Отбор | D38: =D37-$N$6 -> 28350 | E38: =(D37-D38)*$L$14 -> 31320 | H38: 5000 | I38: =(H38-H39)*$M$13 -> 0 | J38: =E38+I38 -> 31320 | L38: Предложение | M38: =Предложение!E370 -> 1992.5923
A39: 44050 | C39: Отбор | D39: =D38-$N$6 -> 27900 | E39: =(D38-D39)*$L$14 -> 31320 | H39: 5000 | I39: =(H39-H40)*$M$13 -> 0 | J39: =E39+I39 -> 31320 | K39: Приведенная выручка
A40: 44051 | C40: Отбор | D40: =D39-$N$6 -> 27450 | E40: =(D39-D40)*$L$14 -> 31320 | H40: 5000 | I40: =(H40-H41)*$M$13 -> 0 | J40: =E40+I40 -> 31320 | L40: Контракт | M40: =I371 -> 7.2138326e+08
...

Sheet Предложение
A1: Дата | B1: Хранение | C1: Процесс | D1: Остаток тыс. куб. | E1: Выручка тыс. ЕВРО
A2: 44013 | C2: Отбор | D2: 0 | E2: =(L2+L3)*L5 -> 2950000 | F2: 0 | I2: Остаток газа на ПХГ Австрия, тыс. куб. | L2: 45000
A3: 44014 | D3: 0 | E3: 0 | F3: 0 | I3: Остаток газа на ПХГ Венгрия, тыс. куб. | L3: 5000
A4: 44015 | D4: 0 | E4: 0 | F4: 0 | I4: Хранение в месяц, тыс ЕВРО | L4: 200
A5: 44016 | D5: 0 | E5: 0 | F5: 0 | I5: Цена продажи неотобранного газа ЕВРО/тыс. куб. | L5: 59
A6: 44017 | D6: 0 | E6: 0 | F6: 0 | I6: Суточный отбор Австрия, тыс.куб. | L6: 890
A7: 44018 | D7: 0 | E7: 0 | F7: 0 | I7: Суточная закачка Австрия, тыс. куб | L7: 870
A8: 44019 | D8: 0 | E8: 0 | F8: 0 | I8: Хранение ЕВРО/тыс. куб. | L8: 4
A9: 44020 | D9: 0 | E9: 0 | F9: 0
A10: 44021 | D10: 0 | E10: 0 | F10: 0
A11: 44022 | D11: 0 | E11: 0 | F11: 0
A12: 44023 | D12: 0 | E12: 0 | F12: 0 | J12: VTPA (Австрия) | K12: VTPH (Венгрия)
A13: 44024 | D13: 0 | E13: 0 | F13: 0 | I13: июль 2020 | J13: 67.7 | K13: 88.3
A14: 44025 | D14: 0 | E14: 0 | F14: 0 | I14: август 2020 | J14: 69.6 | K14: 93.8
A15: 44026 | D15: 0 | E15: 0 | F15: 0 | I15: сентябрь 2020 | J15: 76.9 | K15: 103
A16: 44027 | D16: 0 | E16: 0 | F16: 0 | I16: октябрь 2020 | J16: 93.2 | K16: 122.6
A17: 44028 | D17: 0 | E17: 0 | F17: 0 | I17: ноябрь 2020 | J17: 133.7 | K17: 157
A18: 44029 | D18: 0 | E18: 0 | F18: 0 | I18: декабрь 2020 | J18: 133.7 | K18: 168.8
A19: 44030 | D19: 0 | E19: 0 | F19: 0 | I19: январь 2021 | J19: 142 | K19: 172
A20: 44031 | D20: 0 | E20: 0 | F20: 0 | I20: 1 кв. 2021 | J20: 141.1 | K20: 171.2
A21: 44032 | D21: 0 | E21: 0 | F21: 0 | I21: 2 кв. 2021 | J21: 137 | K21: 162.3
A22: 44033 | D22: 0 | E22: 0 | F22: 0
A23: 44034 | D23: 0 | E23: 0 | F23: 0
A24: 44035 | D24: 0 | E24: 0 | F24: 0
A25: 44036 | D25: 0 | E25: 0 | F25: 0
A26: 44037 | D26: 0 | E26: 0 | F26: 0
A27: 44038 | D27: 0 | E27: 0 | F27: 0
A28: 44039 | D28: 0 | E28: 0 | F28: 0
A29: 44040 | D29: 0 | E29: 0 | F29: 0
A30: 44041 | D30: 0 | E30: 0 | F30: 0
A31: 44042 | D31: 0 | E31: 0 | F31: 0
A32: 44043 | D32: 0 | E32: 0 | F32: 0
A33: 44044 | D33: 0 | E33: 0 | F33: 0
... A93: 44104 | D93: 0 | E93: 0 | F93: 0
A94: 44105 | C94: Закачка | D94: =MIN(L7,80000) -> 870 | E94: =-D94*$L$8/30 -> -116 | F94: =-E94 -> 116
A95: 44106 | C95: Закачка | D95: =MIN(D94+$L$7,80000) -> 1740 | E95: =-D95*$L$8/30 -> -232 | F95: =-E95 -> 232
A96: 44107 | C96: Закачка | D96: =MIN(D95+$L$7,80000) -> 2610 | E96: =-D96*$L$8/30 -> -348 | F96: =-E96 -> 348
A97: 44108 | C97: Закачка | D97: =MIN(D96+$L$7,80000) -> 3480 | E97: =-D97*$L$8/30 -> -464 | F97: =-E97 -> 464
A98: 44109 | C98: Закачка | D98: =MIN(D97+$L$7,80000) -> 4350 | E98: =-D98*$L$8/30 -> -580 | F98: =-E98 -> 580
A99: 44110 | C99: Закачка | D99: =MIN(D98+$L$7,80000) -> 5220 | E99: =-D99*$L$8/30 -> -696 | F99: =-E99 -> 696
...
